<?xml version="1.0" ?>
<!-- =================================================================================== -->
<!-- |    This document was autogenerated by xacro from /home/k/ros2_ws/src/my_robot_description/urdf/argo_j8_v2.urdf.xacro | -->
<!-- |    EDITING THIS FILE BY HAND IS NOT RECOMMENDED                                 | -->
<!-- =================================================================================== -->
<!-- =================================================================================== -->
<!-- |    This document was autogenerated by xacro from /home/k/ros2_ws/src/my_robot_description/urdf/argo_j8.urdf.xacro | -->
<!-- |    EDITING THIS FILE BY HAND IS NOT RECOMMENDED                                 | -->
<!-- =================================================================================== -->
<robot name="argo_j8">
  <!-- Specify some standard inertial calculations https://en.wikipedia.org/wiki/List_of_moments_of_inertia -->
  <!-- These make use of xacro's mathematical functionality -->
  <!-- Specify some standard inertial calculations https://en.wikipedia.org/wiki/List_of_moments_of_inertia -->
  <!-- These make use of xacro's mathematical functionality -->
  <!-- Specify some standard inertial calculations https://en.wikipedia.org/wiki/List_of_moments_of_inertia -->
  <!-- These make use of xacro's mathematical functionality -->
  <!-- Specify some standard inertial calculations https://en.wikipedia.org/wiki/List_of_moments_of_inertia -->
  <!-- These make use of xacro's mathematical functionality -->
  <!-- Definicion de xacro ruedas -->
  <!-- Definicion de materiales constantes -->
  <material name="Military green">
    <color rgba="0.29 0.33 0.13 1.0"/>
  </material>
  <material name="black">
    <color rgba="0.0 0.0 0.0 1.0"/>
  </material>
  <material name="blue">
    <color rgba="0.0 1.0 1.0 1.0"/>
  </material>
  <material name="grey">
    <color rgba="0.7 0.7 0.7 1.0"/>
  </material>
  <!-- Chasis -->
  <link name="base_link">
    <visual>
      <geometry>
        <box size="1.40 2.94 0.81"/>
        <!-- Dimensiones en metros -->
      </geometry>
      <origin rpy="0 0 0" xyz="0 0 0"/>
      <material name="Military green"/>
    </visual>
    <collision>
      <geometry>
        <box size="1.40 2.94 0.81"/>
        <!-- Dimensiones en metros -->
      </geometry>
      <origin rpy="0 0 0" xyz="0 0 0"/>
    </collision>
    <inertial>
      <origin rpy="0 0 0" xyz="0 0 0"/>
      <mass value="750"/>
      <inertia ixx="581.2312499999999" ixy="0.0" ixz="0.0" iyy="163.50625" iyz="0.0" izz="662.7249999999999"/>
    </inertial>
  </link>
  <!-- LiDAR, Camaras, y FixPosition -->
  <link name="LiDAR">
    <visual>
      <geometry>
        <cylinder length="0.05" radius="0.1"/>
        <!-- Dimensiones en metros -->
      </geometry>
      <origin rpy="0 0 0" xyz="0 0 0"/>
      <material name="blue"/>
    </visual>
    <collision>
      <geometry>
        <box size="0.2 0.2 0.05"/>
        <!-- Dimensiones en metros -->
      </geometry>
      <origin rpy="0 0 0" xyz="0 0 0"/>
    </collision>
  </link>
  <link name="front_camera">
    <visual>
      <geometry>
        <box size="0.1 0.1 0.1"/>
        <!-- Dimensiones en metros -->
      </geometry>
      <origin rpy="0 0 0" xyz="0 0 0"/>
      <material name="grey"/>
    </visual>
    <collision>
      <geometry>
        <box size="0.1 0.1 0.1"/>
        <!-- Dimensiones en metros -->
      </geometry>
      <origin rpy="0 0 0" xyz="0 0 0"/>
    </collision>
  </link>
  <link name="back_camera">
    <visual>
      <geometry>
        <box size="0.1 0.1 0.1"/>
        <!-- Dimensiones en metros -->
      </geometry>
      <origin rpy="0 0 0" xyz="0 0 0"/>
      <material name="grey"/>
    </visual>
    <collision>
      <geometry>
        <box size="0.1 0.1 0.1"/>
        <!-- Dimensiones en metros -->
      </geometry>
      <origin rpy="0 0 0" xyz="0 0 0"/>
    </collision>
  </link>
  <link name="fix_position">
    <visual>
      <geometry>
        <box size="0.4 0.2 0.2"/>
        <!-- Dimensiones en metros -->
      </geometry>
      <origin rpy="0 0 0" xyz="0 0 0"/>
      <material name="grey"/>
    </visual>
    <collision>
      <geometry>
        <box size="0.4 0.2 0.2"/>
        <!-- Dimensiones en metros -->
      </geometry>
      <origin rpy="0 0 0" xyz="0 0 0"/>
    </collision>
  </link>
  <!-- Definicion de las 8 ruedas (links y joins) -->
  <link name="front_left_wheel">
    <visual>
      <geometry>
        <cylinder length="0.20" radius="0.28"/>
        <!-- Radio y ancho de la rueda -->
      </geometry>
      <origin rpy="0 1.57 0" xyz="0 0 0"/>
      <!-- Radio en radianes -->
      <material name="black"/>
    </visual>
    <collision>
      <geometry>
        <cylinder length="0.20" radius="0.28"/>
        <!-- Radio y ancho de la rueda -->
      </geometry>
      <origin rpy="0 1.57 0" xyz="0 0 0"/>
      <!-- Radio en radianes -->
    </collision>
    <inertial>
      <origin rpy="0 1.57 0" xyz="0 0 0"/>
      <mass value="11"/>
      <inertia ixx="0.2522666666666667" ixy="0.0" ixz="0.0" iyy="0.2522666666666667" iyz="0.0" izz="0.4312000000000001"/>
    </inertial>
  </link>
  <!-- Joint entre chasis y rueda -->
  <joint name="joint_front_left_wheel" type="continuous">
    <parent link="base_link"/>
    <child link="front_left_wheel"/>
    <origin rpy="0 0 0" xyz="-0.7 0.88 -0.325"/>
    <!-- Posición de la rueda con respecto al chasis -->
    <axis xyz="-1 0 0"/>
    <!-- Eje de rotación -->
  </joint>
  <link name="front_right_wheel">
    <visual>
      <geometry>
        <cylinder length="0.20" radius="0.28"/>
        <!-- Radio y ancho de la rueda -->
      </geometry>
      <origin rpy="0 1.57 0" xyz="0 0 0"/>
      <!-- Radio en radianes -->
      <material name="black"/>
    </visual>
    <collision>
      <geometry>
        <cylinder length="0.20" radius="0.28"/>
        <!-- Radio y ancho de la rueda -->
      </geometry>
      <origin rpy="0 1.57 0" xyz="0 0 0"/>
      <!-- Radio en radianes -->
    </collision>
    <inertial>
      <origin rpy="0 1.57 0" xyz="0 0 0"/>
      <mass value="11"/>
      <inertia ixx="0.2522666666666667" ixy="0.0" ixz="0.0" iyy="0.2522666666666667" iyz="0.0" izz="0.4312000000000001"/>
    </inertial>
  </link>
  <!-- Joint entre chasis y rueda -->
  <joint name="joint_front_right_wheel" type="continuous">
    <parent link="base_link"/>
    <child link="front_right_wheel"/>
    <origin rpy="0 0 0" xyz="0.7 0.88 -0.325"/>
    <!-- Posición de la rueda con respecto al chasis -->
    <axis xyz="-1 0 0"/>
    <!-- Eje de rotación -->
  </joint>
  <link name="midfront_left_wheel">
    <visual>
      <geometry>
        <cylinder length="0.20" radius="0.28"/>
        <!-- Radio y ancho de la rueda -->
      </geometry>
      <origin rpy="0 1.57 0" xyz="0 0 0"/>
      <!-- Radio en radianes -->
      <material name="black"/>
    </visual>
    <collision>
      <geometry>
        <cylinder length="0.20" radius="0.28"/>
        <!-- Radio y ancho de la rueda -->
      </geometry>
      <origin rpy="0 1.57 0" xyz="0 0 0"/>
      <!-- Radio en radianes -->
    </collision>
    <inertial>
      <origin rpy="0 1.57 0" xyz="0 0 0"/>
      <mass value="11"/>
      <inertia ixx="0.2522666666666667" ixy="0.0" ixz="0.0" iyy="0.2522666666666667" iyz="0.0" izz="0.4312000000000001"/>
    </inertial>
  </link>
  <!-- Joint entre chasis y rueda -->
  <joint name="joint_midfront_left_wheel" type="continuous">
    <parent link="base_link"/>
    <child link="midfront_left_wheel"/>
    <origin rpy="0 0 0" xyz="-0.7 0.19 -0.325"/>
    <!-- Posición de la rueda con respecto al chasis -->
    <axis xyz="-1 0 0"/>
    <!-- Eje de rotación -->
  </joint>
  <link name="midfront_right_wheel">
    <visual>
      <geometry>
        <cylinder length="0.20" radius="0.28"/>
        <!-- Radio y ancho de la rueda -->
      </geometry>
      <origin rpy="0 1.57 0" xyz="0 0 0"/>
      <!-- Radio en radianes -->
      <material name="black"/>
    </visual>
    <collision>
      <geometry>
        <cylinder length="0.20" radius="0.28"/>
        <!-- Radio y ancho de la rueda -->
      </geometry>
      <origin rpy="0 1.57 0" xyz="0 0 0"/>
      <!-- Radio en radianes -->
    </collision>
    <inertial>
      <origin rpy="0 1.57 0" xyz="0 0 0"/>
      <mass value="11"/>
      <inertia ixx="0.2522666666666667" ixy="0.0" ixz="0.0" iyy="0.2522666666666667" iyz="0.0" izz="0.4312000000000001"/>
    </inertial>
  </link>
  <!-- Joint entre chasis y rueda -->
  <joint name="joint_midfront_right_wheel" type="continuous">
    <parent link="base_link"/>
    <child link="midfront_right_wheel"/>
    <origin rpy="0 0 0" xyz="0.7 0.19 -0.325"/>
    <!-- Posición de la rueda con respecto al chasis -->
    <axis xyz="-1 0 0"/>
    <!-- Eje de rotación -->
  </joint>
  <link name="midback_left_wheel">
    <visual>
      <geometry>
        <cylinder length="0.20" radius="0.28"/>
        <!-- Radio y ancho de la rueda -->
      </geometry>
      <origin rpy="0 1.57 0" xyz="0 0 0"/>
      <!-- Radio en radianes -->
      <material name="black"/>
    </visual>
    <collision>
      <geometry>
        <cylinder length="0.20" radius="0.28"/>
        <!-- Radio y ancho de la rueda -->
      </geometry>
      <origin rpy="0 1.57 0" xyz="0 0 0"/>
      <!-- Radio en radianes -->
    </collision>
    <inertial>
      <origin rpy="0 1.57 0" xyz="0 0 0"/>
      <mass value="11"/>
      <inertia ixx="0.2522666666666667" ixy="0.0" ixz="0.0" iyy="0.2522666666666667" iyz="0.0" izz="0.4312000000000001"/>
    </inertial>
  </link>
  <!-- Joint entre chasis y rueda -->
  <joint name="joint_midback_left_wheel" type="continuous">
    <parent link="base_link"/>
    <child link="midback_left_wheel"/>
    <origin rpy="0 0 0" xyz="-0.7 -0.5 -0.325"/>
    <!-- Posición de la rueda con respecto al chasis -->
    <axis xyz="-1 0 0"/>
    <!-- Eje de rotación -->
  </joint>
  <link name="midback_right_wheel">
    <visual>
      <geometry>
        <cylinder length="0.20" radius="0.28"/>
        <!-- Radio y ancho de la rueda -->
      </geometry>
      <origin rpy="0 1.57 0" xyz="0 0 0"/>
      <!-- Radio en radianes -->
      <material name="black"/>
    </visual>
    <collision>
      <geometry>
        <cylinder length="0.20" radius="0.28"/>
        <!-- Radio y ancho de la rueda -->
      </geometry>
      <origin rpy="0 1.57 0" xyz="0 0 0"/>
      <!-- Radio en radianes -->
    </collision>
    <inertial>
      <origin rpy="0 1.57 0" xyz="0 0 0"/>
      <mass value="11"/>
      <inertia ixx="0.2522666666666667" ixy="0.0" ixz="0.0" iyy="0.2522666666666667" iyz="0.0" izz="0.4312000000000001"/>
    </inertial>
  </link>
  <!-- Joint entre chasis y rueda -->
  <joint name="joint_midback_right_wheel" type="continuous">
    <parent link="base_link"/>
    <child link="midback_right_wheel"/>
    <origin rpy="0 0 0" xyz="0.7 -0.5 -0.325"/>
    <!-- Posición de la rueda con respecto al chasis -->
    <axis xyz="-1 0 0"/>
    <!-- Eje de rotación -->
  </joint>
  <link name="back_left_wheel">
    <visual>
      <geometry>
        <cylinder length="0.20" radius="0.28"/>
        <!-- Radio y ancho de la rueda -->
      </geometry>
      <origin rpy="0 1.57 0" xyz="0 0 0"/>
      <!-- Radio en radianes -->
      <material name="black"/>
    </visual>
    <collision>
      <geometry>
        <cylinder length="0.20" radius="0.28"/>
        <!-- Radio y ancho de la rueda -->
      </geometry>
      <origin rpy="0 1.57 0" xyz="0 0 0"/>
      <!-- Radio en radianes -->
    </collision>
    <inertial>
      <origin rpy="0 1.57 0" xyz="0 0 0"/>
      <mass value="11"/>
      <inertia ixx="0.2522666666666667" ixy="0.0" ixz="0.0" iyy="0.2522666666666667" iyz="0.0" izz="0.4312000000000001"/>
    </inertial>
  </link>
  <!-- Joint entre chasis y rueda -->
  <joint name="joint_back_left_wheel" type="continuous">
    <parent link="base_link"/>
    <child link="back_left_wheel"/>
    <origin rpy="0 0 0" xyz="-0.7 -1.19 -0.325"/>
    <!-- Posición de la rueda con respecto al chasis -->
    <axis xyz="-1 0 0"/>
    <!-- Eje de rotación -->
  </joint>
  <link name="back_right_wheel">
    <visual>
      <geometry>
        <cylinder length="0.20" radius="0.28"/>
        <!-- Radio y ancho de la rueda -->
      </geometry>
      <origin rpy="0 1.57 0" xyz="0 0 0"/>
      <!-- Radio en radianes -->
      <material name="black"/>
    </visual>
    <collision>
      <geometry>
        <cylinder length="0.20" radius="0.28"/>
        <!-- Radio y ancho de la rueda -->
      </geometry>
      <origin rpy="0 1.57 0" xyz="0 0 0"/>
      <!-- Radio en radianes -->
    </collision>
    <inertial>
      <origin rpy="0 1.57 0" xyz="0 0 0"/>
      <mass value="11"/>
      <inertia ixx="0.2522666666666667" ixy="0.0" ixz="0.0" iyy="0.2522666666666667" iyz="0.0" izz="0.4312000000000001"/>
    </inertial>
  </link>
  <!-- Joint entre chasis y rueda -->
  <joint name="joint_back_right_wheel" type="continuous">
    <parent link="base_link"/>
    <child link="back_right_wheel"/>
    <origin rpy="0 0 0" xyz="0.7 -1.19 -0.325"/>
    <!-- Posición de la rueda con respecto al chasis -->
    <axis xyz="-1 0 0"/>
    <!-- Eje de rotación -->
  </joint>
  <!-- Link virtual para base del plano.  -->
  <link name="base_footprint"/>
  <!-- Joint de referencia de la base del plano y Argo J8 -->
  <joint name="joint_base_footprint" type="fixed">
    <parent link="base_link"/>
    <child link="base_footprint"/>
    <origin rpy="0 0 0" xyz="0 0 -0.605"/>
    <!-- Posición de la rueda con respecto al chasis -->
  </joint>
  <!-- Definicion de Joints entre chasis y LiDAR, cámara y FixPosition con chasis -->
  <!-- Joint entre chasis y LiDAR -->
  <joint name="joint_LiDAR" type="fixed">
    <parent link="base_link"/>
    <child link="LiDAR"/>
    <origin rpy="0 0 1.57" xyz="0 1.47 0"/>
    <!-- Posición del LiDAR con respecto al chasis -->
  </joint>
  <!-- Joint entre chasis y camaras -->
  <joint name="joint_front_camera" type="fixed">
    <parent link="base_link"/>
    <child link="front_camera"/>
    <origin rpy="0 0 0" xyz="0 1.06 0.405"/>
    <!-- Posición de la camara con respecto al chasis -->
  </joint>
  <joint name="joint_back_camera" type="fixed">
    <parent link="base_link"/>
    <child link="back_camera"/>
    <origin rpy="0 0 0" xyz="0 0.96 0.405"/>
    <!-- Posición de la camara con respecto al chasis -->
  </joint>
  <!-- Joint entre chasis y FixPosition -->
  <joint name="joint_fix_position" type="fixed">
    <parent link="base_link"/>
    <child link="fix_position"/>
    <origin rpy="0 0 0" xyz="0.35 1.01 0.405"/>
    <!-- Posición del LiDAR con respecto al chasis -->
  </joint>
</robot>
