<?xml version="1.0" ?>
<!-- =================================================================================== -->
<!-- |    This document was autogenerated by xacro from argo_j8.urdf.xacro             | -->
<!-- |    EDITING THIS FILE BY HAND IS NOT RECOMMENDED                                 | -->
<!-- =================================================================================== -->
<robot name="argo">
  <!-- URDF for Argo Robot -->
  <!-- Automatically created by SolidWorks to URDF Exporter -->
  <!-- Exporter Version: 1.6.0-4-g7f85cfe, Build: 1.6.7995.38578 -->
  <!-- IMU sensor configuration for the upper case -->
  <gazebo reference="base_link">
    <sensor name="fixposition_poi_imu" type="imu">
      <always_on>true</always_on>
      <update_rate>200</update_rate>
      <plugin filename="libgazebo_ros_imu_sensor.so" name="fixposition_raw_imu_node">
        <ros>
          <namespace>/fixposition</namespace>
          <remapping>~/out:=raw_imu</remapping>
          <frame_name>FP_VRTK</frame_name>
        </ros>
        <initial_orientation_as_reference>false</initial_orientation_as_reference>
      </plugin>
    </sensor>
  </gazebo>
  <!-- IMU sensor configuration for the upper case -->
  <gazebo reference="base_link">
    <sensor name="fixposition_raw_imu" type="imu">
      <always_on>true</always_on>
      <update_rate>200</update_rate>
      <plugin filename="libgazebo_ros_imu_sensor.so" name="fixposition_poi_imu_node">
        <ros>
          <namespace>/fixposition</namespace>
          <remapping>~/out:=poiimu</remapping>
          <frame_name>FP_POI</frame_name>
        </ros>
        <initial_orientation_as_reference>false</initial_orientation_as_reference>
      </plugin>
    </sensor>
  </gazebo>
  <!--<xacro:include filename="$(find zed_camera_pkg)/urdf/camera_macro.urdf"/>-->
  <!-- Base Link -->
  <link name="base_link">
    <inertial>
      <origin rpy="0 0 0" xyz="-0.042688 0.0075201 0.060368"/>
      <mass value="1000.6"/>
      <inertia ixx="162.15" ixy="-2.4702E-05" ixz="-5.0479" iyy="867.35" iyz="-3.1093E-05" izz="5000.46"/>
    </inertial>
    <visual>
      <origin rpy="0 0 0" xyz="0 0 0"/>
      <geometry>
        <mesh filename="package://my_robot_description/meshes/base_link.STL"/>
      </geometry>
      <material name="">
        <color rgba="0.50196 0.50196 0.50196 1"/>
      </material>
    </visual>
    <collision>
      <origin rpy="0 0 0" xyz="0 0 0"/>
      <geometry>
        <mesh filename="package://my_robot_description/meshes/base_link.STL"/>
      </geometry>
    </collision>
  </link>
  <gazebo reference="base_link">
    <visual>
      <material>
        <ambient>0.3 0.3 0.3 1.0</ambient>
        <diffuse>0.3 0.3 0.3 1.0</diffuse>
        <specular>0.3 0.3 0.3 1.0</specular>
        <emissive>0 0 0 0</emissive>
      </material>
    </visual>
    <preserveFixedJoint>true</preserveFixedJoint>
    <!-- Also preserve joint if has a fixed joint -->
  </gazebo>
  <!-- Dark Grey -->
  <!-- J8 Top Link -->
  <link name="J8_top">
    <inertial>
      <origin rpy="0 0 0" xyz="0.36558 -4.2501E-17 0.10133"/>
      <mass value="639.03"/>
      <inertia ixx="110.75" ixy="3.1317E-14" ixz="-25.628" iyy="522.18" iyz="6.8087E-15" izz="2000.13"/>
    </inertial>
    <visual>
      <origin rpy="0 0 0" xyz="0 0 0"/>
      <geometry>
        <mesh filename="package://my_robot_description/meshes/J8_top.STL"/>
      </geometry>
      <material name="">
        <color rgba="0.4 0.48627 0.24314 1"/>
      </material>
    </visual>
    <collision>
      <origin rpy="0 0 0" xyz="0 0 0"/>
      <geometry>
        <mesh filename="package://my_robot_description/meshes/J8_top.STL"/>
      </geometry>
    </collision>
  </link>
  <gazebo reference="J8_top">
    <visual>
      <material>
        <ambient>0.2941 0.3255 0.1255 1.0</ambient>
        <diffuse>0.2941 0.3255 0.1255 1.0</diffuse>
        <specular>0.2941 0.3255 0.1255 1.0</specular>
        <emissive>0 0 0 0</emissive>
      </material>
    </visual>
    <preserveFixedJoint>true</preserveFixedJoint>
    <!-- Also preserve joint if has a fixed joint -->
  </gazebo>
  <!-- Military Green -->
  <!-- Joint Between Top and Base -->
  <joint name="Top_Base_joint" type="fixed">
    <origin rpy="0 0 0" xyz="-0.0093372 0.0075201 0.265"/>
    <parent link="base_link"/>
    <child link="J8_top"/>
    <axis xyz="0 0 0"/>
  </joint>
  <!-- Bridge Link -->
  <link name="Bridge">
    <inertial>
      <origin rpy="0 0 0" xyz="-4.4409E-16 0.0076101 0.13629"/>
      <mass value="7.6437"/>
      <inertia ixx="1.3715" ixy="4.0621E-14" ixz="-8.0678E-18" iyy="0.083158" iyz="-4.1934E-15" izz="1.3176"/>
    </inertial>
    <visual>
      <origin rpy="0 0 0" xyz="0 0 0"/>
      <geometry>
        <mesh filename="package://my_robot_description/meshes/Bridge.STL"/>
      </geometry>
      <material name="">
        <color rgba="0.4 0.48627 0.24314 1"/>
      </material>
    </visual>
    <collision>
      <origin rpy="0 0 0" xyz="0 0 0"/>
      <geometry>
        <mesh filename="package://my_robot_description/meshes/Bridge.STL"/>
      </geometry>
    </collision>
  </link>
  <gazebo reference="Bridge">
    <visual>
      <material>
        <ambient>0.2941 0.3255 0.1255 1.0</ambient>
        <diffuse>0.2941 0.3255 0.1255 1.0</diffuse>
        <specular>0.2941 0.3255 0.1255 1.0</specular>
        <emissive>0 0 0 0</emissive>
      </material>
    </visual>
    <preserveFixedJoint>true</preserveFixedJoint>
    <!-- Also preserve joint if has a fixed joint -->
  </gazebo>
  <!-- Military Green -->
  <!-- Joint Between Bridge and Top -->
  <joint name="Top_Bridge_joint" type="fixed">
    <origin rpy="0 0 0" xyz="0.82 0 0.31021"/>
    <parent link="J8_top"/>
    <child link="Bridge"/>
    <axis xyz="0 0 0"/>
  </joint>
  <link name="Bridge_panel_1">
    <inertial>
      <origin rpy="0 0 0" xyz="-0.2533 -0.13389 0.21171"/>
      <mass value="0.12712"/>
      <inertia ixx="0.0014232" ixy="-7.4618E-06" ixz="4.8219E-08" iyy="0.0014347" iyz="1.7036E-09" izz="0.00022938"/>
    </inertial>
    <visual>
      <origin rpy="0 0 0" xyz="0 0 0"/>
      <geometry>
        <mesh filename="package://my_robot_description/meshes/Bridge_panel_1.STL"/>
      </geometry>
      <material name="">
        <color rgba="0.4 0.48627 0.24314 1"/>
      </material>
    </visual>
    <collision>
      <origin rpy="0 0 0" xyz="0 0 0"/>
      <geometry>
        <mesh filename="package://my_robot_description/meshes/Bridge_panel_1.STL"/>
      </geometry>
    </collision>
  </link>
  <gazebo reference="Bridge_panel_1">
    <visual>
      <material>
        <ambient>0.2941 0.3255 0.1255 1.0</ambient>
        <diffuse>0.2941 0.3255 0.1255 1.0</diffuse>
        <specular>0.2941 0.3255 0.1255 1.0</specular>
        <emissive>0 0 0 0</emissive>
      </material>
    </visual>
    <preserveFixedJoint>true</preserveFixedJoint>
    <!-- Also preserve joint if has a fixed joint -->
  </gazebo>
  <!-- Military Green -->
  <joint name="Bridge_panel_1_joint" type="fixed">
    <origin rpy="1.5708 0 0" xyz="0.2533 0.14912 0.21171"/>
    <parent link="Bridge"/>
    <child link="Bridge_panel_1"/>
    <axis xyz="0 0 0"/>
  </joint>
  <link name="Bridge_panel_2">
    <inertial>
      <origin rpy="0 0 0" xyz="-0.2533 -0.13389 0.21171"/>
      <mass value="0.12712"/>
      <inertia ixx="0.0014232" ixy="-7.4618E-06" ixz="4.8219E-08" iyy="0.0014347" iyz="1.7036E-09" izz="0.00022938"/>
    </inertial>
    <visual>
      <origin rpy="0 0 0" xyz="0 0 0"/>
      <geometry>
        <mesh filename="package://my_robot_description/meshes/Bridge_panel_2.STL"/>
      </geometry>
      <material name="">
        <color rgba="0.4 0.48627 0.24314 1"/>
      </material>
    </visual>
    <collision>
      <origin rpy="0 0 0" xyz="0 0 0"/>
      <geometry>
        <mesh filename="package://my_robot_description/meshes/Bridge_panel_2.STL"/>
      </geometry>
    </collision>
  </link>
  <gazebo reference="Bridge_panel_2">
    <visual>
      <material>
        <ambient>0.2941 0.3255 0.1255 1.0</ambient>
        <diffuse>0.2941 0.3255 0.1255 1.0</diffuse>
        <specular>0.2941 0.3255 0.1255 1.0</specular>
        <emissive>0 0 0 0</emissive>
      </material>
    </visual>
    <preserveFixedJoint>true</preserveFixedJoint>
    <!-- Also preserve joint if has a fixed joint -->
  </gazebo>
  <!-- Military Green -->
  <joint name="Bridge_panel_2_joint" type="fixed">
    <origin rpy="1.5708 0 -3.1416" xyz="-0.2533 0.15172 0.21171"/>
    <parent link="Bridge"/>
    <child link="Bridge_panel_2"/>
    <axis xyz="0 0 0"/>
  </joint>
  <link name="Bridge_panel_3">
    <inertial>
      <origin rpy="0 0 0" xyz="-0.2533 -0.13389 0.21171"/>
      <mass value="0.12712"/>
      <inertia ixx="0.0014232" ixy="-7.4618E-06" ixz="4.8219E-08" iyy="0.0014347" iyz="1.7036E-09" izz="0.00022938"/>
    </inertial>
    <visual>
      <origin rpy="0 0 0" xyz="0 0 0"/>
      <geometry>
        <mesh filename="package://my_robot_description/meshes/Bridge_panel_3.STL"/>
      </geometry>
      <material name="">
        <color rgba="0.4 0.48627 0.24314 1"/>
      </material>
    </visual>
    <collision>
      <origin rpy="0 0 0" xyz="0 0 0"/>
      <geometry>
        <mesh filename="package://my_robot_description/meshes/Bridge_panel_3.STL"/>
      </geometry>
    </collision>
  </link>
  <gazebo reference="Bridge_panel_3">
    <visual>
      <material>
        <ambient>0.2941 0.3255 0.1255 1.0</ambient>
        <diffuse>0.2941 0.3255 0.1255 1.0</diffuse>
        <specular>0.2941 0.3255 0.1255 1.0</specular>
        <emissive>0 0 0 0</emissive>
      </material>
    </visual>
    <preserveFixedJoint>true</preserveFixedJoint>
    <!-- Also preserve joint if has a fixed joint -->
  </gazebo>
  <!-- Military Green -->
  <joint name="Bridge_panel_3_joint" type="fixed">
    <origin rpy="1.5708 0 0" xyz="0.2533 -0.1365 0.21171"/>
    <parent link="Bridge"/>
    <child link="Bridge_panel_3"/>
    <axis xyz="0 0 0"/>
  </joint>
  <link name="Bridge_panel_4">
    <inertial>
      <origin rpy="0 0 0" xyz="-0.2533 -0.13389 0.21171"/>
      <mass value="0.12712"/>
      <inertia ixx="0.0014232" ixy="-7.4618E-06" ixz="4.8219E-08" iyy="0.0014347" iyz="1.7036E-09" izz="0.00022938"/>
    </inertial>
    <visual>
      <origin rpy="0 0 0" xyz="0 0 0"/>
      <geometry>
        <mesh filename="package://my_robot_description/meshes/Bridge_panel_4.STL"/>
      </geometry>
      <material name="">
        <color rgba="0.4 0.48627 0.24314 1"/>
      </material>
    </visual>
    <collision>
      <origin rpy="0 0 0" xyz="0 0 0"/>
      <geometry>
        <mesh filename="package://my_robot_description/meshes/Bridge_panel_4.STL"/>
      </geometry>
    </collision>
  </link>
  <gazebo reference="Bridge_panel_4">
    <visual>
      <material>
        <ambient>0.2941 0.3255 0.1255 1.0</ambient>
        <diffuse>0.2941 0.3255 0.1255 1.0</diffuse>
        <specular>0.2941 0.3255 0.1255 1.0</specular>
        <emissive>0 0 0 0</emissive>
      </material>
    </visual>
    <preserveFixedJoint>true</preserveFixedJoint>
    <!-- Also preserve joint if has a fixed joint -->
  </gazebo>
  <!-- Military Green -->
  <joint name="Bridge_panel_4_joint" type="fixed">
    <origin rpy="1.5708 0 -3.1416" xyz="-0.2533 -0.13389 0.21171"/>
    <parent link="Bridge"/>
    <child link="Bridge_panel_4"/>
    <axis xyz="0 0 0"/>
  </joint>
  <link name="Left_bar">
    <inertial>
      <origin rpy="0 0 0" xyz="0.45 0.073187 0.020151"/>
      <mass value="2.4389"/>
      <inertia ixx="0.002886" ixy="0" ixz="0" iyy="1.1032" iyz="-0.00029921" izz="1.1009"/>
    </inertial>
    <visual>
      <origin rpy="0 0 0" xyz="0 0 0"/>
      <geometry>
        <mesh filename="package://my_robot_description/meshes/Left_bar.STL"/>
      </geometry>
      <!-- The color is defined in the main file or through a gazebo tag -->
    </visual>
    <collision>
      <origin rpy="0 0 0" xyz="0 0 0"/>
      <geometry>
        <mesh filename="package://my_robot_description/meshes/Left_bar.STL"/>
      </geometry>
    </collision>
  </link>
  <gazebo reference="Left_bar">
    <visual>
      <material>
        <ambient>0.2941 0.3255 0.1255 1.0</ambient>
        <diffuse>0.2941 0.3255 0.1255 1.0</diffuse>
        <specular>0.2941 0.3255 0.1255 1.0</specular>
        <emissive>0 0 0 0</emissive>
      </material>
    </visual>
    <preserveFixedJoint>true</preserveFixedJoint>
    <!-- Also preserve joint if has a fixed joint -->
  </gazebo>
  <!-- Military Green -->
  <joint name="Left_bar_joint" type="fixed">
    <origin rpy="3.1416 0 0" xyz="-0.7165 0.7825 0.185"/>
    <parent link="J8_top"/>
    <child link="Left_bar"/>
    <axis xyz="0 0 0"/>
  </joint>
  <link name="Right_bar">
    <inertial>
      <origin rpy="0 0 0" xyz="0.45 0.073187 0.020151"/>
      <mass value="2.4389"/>
      <inertia ixx="0.002886" ixy="0" ixz="0" iyy="1.1032" iyz="-0.00029921" izz="1.1009"/>
    </inertial>
    <visual>
      <origin rpy="0 0 0" xyz="0 0 0"/>
      <geometry>
        <mesh filename="package://my_robot_description/meshes/Right_bar.STL"/>
      </geometry>
      <!-- The color is defined in the main file or through a gazebo tag -->
    </visual>
    <collision>
      <origin rpy="0 0 0" xyz="0 0 0"/>
      <geometry>
        <mesh filename="package://my_robot_description/meshes/Right_bar.STL"/>
      </geometry>
    </collision>
  </link>
  <gazebo reference="Right_bar">
    <visual>
      <material>
        <ambient>0.2941 0.3255 0.1255 1.0</ambient>
        <diffuse>0.2941 0.3255 0.1255 1.0</diffuse>
        <specular>0.2941 0.3255 0.1255 1.0</specular>
        <emissive>0 0 0 0</emissive>
      </material>
    </visual>
    <preserveFixedJoint>true</preserveFixedJoint>
    <!-- Also preserve joint if has a fixed joint -->
  </gazebo>
  <!-- Military Green -->
  <joint name="Right_bar_joint" type="fixed">
    <origin rpy="3.1416 0 0" xyz="-0.7165 -0.7125 0.185"/>
    <parent link="J8_top"/>
    <child link="Right_bar"/>
    <axis xyz="0 0 0"/>
  </joint>
  <link name="Left_gps_holder">
    <inertial>
      <origin rpy="0 0 0" xyz="0.028467 0.0040708 0.064445"/>
      <mass value="0.085883"/>
      <inertia ixx="4.8874E-05" ixy="1.086E-09" ixz="1.7125E-08" iyy="6.5272E-05" iyz="-6.869E-06" izz="3.5166E-05"/>
    </inertial>
    <visual>
      <origin rpy="0 0 0" xyz="0 0 0"/>
      <geometry>
        <mesh filename="package://my_robot_description/meshes/Right_gps_holder.STL"/>
      </geometry>
      <material name="">
        <color rgba="0.4 0.48627 0.24314 1"/>
      </material>
    </visual>
    <collision>
      <origin rpy="0 0 0" xyz="0 0 0"/>
      <geometry>
        <mesh filename="package://my_robot_description/meshes/Right_gps_holder.STL"/>
      </geometry>
    </collision>
  </link>
  <gazebo reference="Left_gps_holder">
    <visual>
      <material>
        <ambient>0.2941 0.3255 0.1255 1.0</ambient>
        <diffuse>0.2941 0.3255 0.1255 1.0</diffuse>
        <specular>0.2941 0.3255 0.1255 1.0</specular>
        <emissive>0 0 0 0</emissive>
      </material>
    </visual>
    <preserveFixedJoint>true</preserveFixedJoint>
    <!-- Also preserve joint if has a fixed joint -->
  </gazebo>
  <!-- Military Green -->
  <joint name="Left_gps_holder_joint" type="fixed">
    <origin rpy="1.5708 0 1.5708" xyz="-0.007 0.601 0.21421"/>
    <parent link="Bridge"/>
    <child link="Left_gps_holder"/>
    <axis xyz="0 0 0"/>
  </joint>
  <link name="Right_gps_holder">
    <inertial>
      <origin rpy="0 0 0" xyz="0.028467 0.0040708 0.064445"/>
      <mass value="0.085883"/>
      <inertia ixx="4.8874E-05" ixy="1.086E-09" ixz="1.7125E-08" iyy="6.5272E-05" iyz="-6.869E-06" izz="3.5166E-05"/>
    </inertial>
    <visual>
      <origin rpy="0 0 0" xyz="0 0 0"/>
      <geometry>
        <mesh filename="package://my_robot_description/meshes/Right_gps_holder.STL"/>
      </geometry>
      <material name="">
        <color rgba="0.4 0.48627 0.24314 1"/>
      </material>
    </visual>
    <collision>
      <origin rpy="0 0 0" xyz="0 0 0"/>
      <geometry>
        <mesh filename="package://my_robot_description/meshes/Right_gps_holder.STL"/>
      </geometry>
    </collision>
  </link>
  <gazebo reference="Right_gps_holder">
    <visual>
      <material>
        <ambient>0.2941 0.3255 0.1255 1.0</ambient>
        <diffuse>0.2941 0.3255 0.1255 1.0</diffuse>
        <specular>0.2941 0.3255 0.1255 1.0</specular>
        <emissive>0 0 0 0</emissive>
      </material>
    </visual>
    <preserveFixedJoint>true</preserveFixedJoint>
    <!-- Also preserve joint if has a fixed joint -->
  </gazebo>
  <!-- Military Green -->
  <joint name="Right_gps_holder_joint" type="fixed">
    <origin rpy="1.5708 0 1.5708" xyz="-0.007 -0.51339 0.21421"/>
    <parent link="Bridge"/>
    <child link="Right_gps_holder"/>
    <axis xyz="0 0 0"/>
  </joint>
  <link name="Left_gps">
    <inertial>
      <origin rpy="0 0 0" xyz="0.0001309 0.0375 0.010255"/>
      <mass value="0.07021"/>
      <inertia ixx="2.1784E-05" ixy="2.6915E-11" ixz="-1.5698E-09" iyy="2.0279E-05" iyz="5.606E-12" izz="3.6479E-05"/>
    </inertial>
    <visual>
      <origin rpy="0 0 0" xyz="0 0 0"/>
      <geometry>
        <mesh filename="package://my_robot_description/meshes/Left_gps.STL"/>
      </geometry>
      <material name="">
        <color rgba="0.64706 0.51373 0 1"/>
      </material>
    </visual>
    <collision>
      <origin rpy="0 0 0" xyz="0 0 0"/>
      <geometry>
        <mesh filename="package://my_robot_description/meshes/Left_gps.STL"/>
      </geometry>
    </collision>
  </link>
  <joint name="Left_gps_joint" type="fixed">
    <origin rpy="1.5708 1.5708 3.141592653589793" xyz="-0.066 0.012 -0.066"/>
    <parent link="Left_gps_holder"/>
    <child link="Left_gps"/>
    <axis xyz="0 0 0"/>
  </joint>
  <link name="Right_gps">
    <inertial>
      <origin rpy="0 0 0" xyz="0.0001309 0.0375 0.010255"/>
      <mass value="0.07021"/>
      <inertia ixx="2.1784E-05" ixy="2.6915E-11" ixz="-1.5698E-09" iyy="2.0279E-05" iyz="5.606E-12" izz="3.6479E-05"/>
    </inertial>
    <visual>
      <origin rpy="0 0 0" xyz="0 0 0"/>
      <geometry>
        <mesh filename="package://my_robot_description/meshes/Left_gps.STL"/>
      </geometry>
      <material name="">
        <color rgba="0.64706 0.51373 0 1"/>
      </material>
    </visual>
    <collision>
      <origin rpy="0 0 0" xyz="0 0 0"/>
      <geometry>
        <mesh filename="package://my_robot_description/meshes/Left_gps.STL"/>
      </geometry>
    </collision>
  </link>
  <joint name="Right_gps_joint" type="fixed">
    <origin rpy="1.5708 1.5708 3.141592653589793" xyz="-0.066 0.012 -0.066"/>
    <parent link="Right_gps_holder"/>
    <child link="Right_gps"/>
    <axis xyz="0 0 0"/>
  </joint>
  <link name="Velodyne_link">
    <inertial>
      <origin rpy="0 0 0" xyz="1.6279 -0.0022244 0.17"/>
      <mass value="0.61592"/>
      <inertia ixx="0.00069055" ixy="0" ixz="0" iyy="0.0006838" iyz="0" izz="0.00083911"/>
    </inertial>
    <visual>
      <origin rpy="0 0 0" xyz="0 0 0"/>
      <geometry>
        <mesh filename="package://my_robot_description/meshes/Velodyne.STL"/>
      </geometry>
      <!-- Default color for all lidars -->
      <material name="">
        <color rgba="0.5 0.5 0.5 1"/>
      </material>
    </visual>
    <collision>
      <origin rpy="0 0 0" xyz="0 0 0"/>
      <geometry>
        <mesh filename="package://my_robot_description/meshes/Velodyne.STL"/>
      </geometry>
    </collision>
  </link>
  <joint name="Velodyne_joint" type="fixed">
    <origin rpy="0 0 0" xyz="1.6279 -0.0022244 0.17"/>
    <parent link="J8_top"/>
    <child link="Velodyne_link"/>
    <axis xyz="0 0 0"/>
  </joint>
  <gazebo reference="Velodyne_link">
    <visual>
      <material>
        <ambient>0.8 0.8 0.8 1.0</ambient>
        <diffuse>0.8 0.8 0.8 1.0</diffuse>
        <specular>0.8 0.8 0.8 1.0</specular>
        <emissive>0 0 0 0</emissive>
      </material>
    </visual>
    <preserveFixedJoint>true</preserveFixedJoint>
    <!-- Also preserve joint if has a fixed joint -->
  </gazebo>
  <!-- Light Grey -->
  <link name="Sick_link">
    <inertial>
      <origin rpy="0 0 0" xyz="1.50 0.02 0.27732"/>
      <mass value="0.22144"/>
      <inertia ixx="0.00069055" ixy="0" ixz="0" iyy="0.0006838" iyz="0" izz="0.00083911"/>
    </inertial>
    <visual>
      <origin rpy="0 0 0" xyz="0 0 0"/>
      <geometry>
        <mesh filename="package://my_robot_description/meshes/Sick.STL"/>
      </geometry>
      <!-- Default color for all lidars -->
      <material name="">
        <color rgba="0.5 0.5 0.5 1"/>
      </material>
    </visual>
    <collision>
      <origin rpy="0 0 0" xyz="0 0 0"/>
      <geometry>
        <mesh filename="package://my_robot_description/meshes/Sick.STL"/>
      </geometry>
    </collision>
  </link>
  <joint name="Sick_joint" type="fixed">
    <origin rpy="0 0 0" xyz="1.50 0.02 0.27732"/>
    <parent link="J8_top"/>
    <child link="Sick_link"/>
    <axis xyz="0 0 0"/>
  </joint>
  <gazebo reference="Sick_link">
    <visual>
      <material>
        <ambient>0.8 0.8 0.8 1.0</ambient>
        <diffuse>0.8 0.8 0.8 1.0</diffuse>
        <specular>0.8 0.8 0.8 1.0</specular>
        <emissive>0 0 0 0</emissive>
      </material>
    </visual>
    <preserveFixedJoint>true</preserveFixedJoint>
    <!-- Also preserve joint if has a fixed joint -->
  </gazebo>
  <!-- Light Grey -->
  <!-- Front and Back Camera 
  <xacro:camera name="Back_camera" parent="Bridge" origin_xyz="-0.11 0 0.18021" origin_rpy="0 1.5708 0" ros_topic="/back_camera"/>
  <xacro:camera name="Front_camera" parent="Bridge" origin_xyz="0.11 0 0.18021" origin_rpy="0 1.5708 0" ros_topic="/front_camera"/>-->
  <!-- Zedd Camera 
  <xacro:zed_camera name="zed_camera" parent="Bridge" origin_xyz="0.11 0 0.23" origin_rpy="0 ${M_PI} 0" ros_topic="/zedd_camera"/>-->
  <!-- Suspension Link -->
  <link name="Suspension_1">
    <inertial>
      <origin rpy="0 0 0" xyz="4.4409E-16 -0.005 2.2204E-16"/>
      <mass value="10.0"/>
      <inertia ixx="5.0" ixy="8.0515E-20" ixz="0" iyy="5.0" iyz="1.9328E-19" izz="5.0"/>
    </inertial>
    <visual>
      <origin rpy="0 0 0" xyz="0 0 0"/>
      <geometry>
        <mesh filename="package://my_robot_description/meshes/Suspension_1.STL"/>
      </geometry>
      <material name="">
        <color rgba="0.79216 0.81961 0.93333 1"/>
      </material>
    </visual>
    <collision>
      <origin rpy="0 0 0" xyz="0 0 0"/>
      <geometry>
        <mesh filename="package://my_robot_description/meshes/Suspension_1.STL"/>
      </geometry>
    </collision>
  </link>
  <!-- Prismatic Joint (Base Link to Suspension) -->
  <joint name="base_Suspension_1_joint" type="prismatic">
    <origin rpy=" 0 0 0 " xyz="-1.0593 -0.45 -0.225"/>
    <parent link="base_link"/>
    <child link="Suspension_1"/>
    <axis xyz="0 0 1"/>
    <limit effort="1000000000000.0" lower="-10.0" upper="10.0" velocity="0.0"/>
    <dynamics damping="100.0" friction="1000000000000.0"/>
  </joint>
  <gazebo reference="base_Suspension_1_joint">
    <implicitSpringDamper>true</implicitSpringDamper>
    <springStiffness>500000000000000</springStiffness>
    <springReference>0.0</springReference>
  </gazebo>
  <link name="Wheel_1">
    <!-- Inertial, visual, and collision properties -->
    <inertial>
      <origin rpy="0 0 0" xyz="0 0.17637 0"/>
      <mass value="5.205463824313"/>
      <inertia ixx="3.66317923670982" ixy="0" ixz="0" iyy="3.66317923670982" iyz="0" izz="5.43484629444829"/>
    </inertial>
    <visual>
      <origin rpy="1.5707963267948966 0 0" xyz="0 0 0"/>
      <geometry>
        <cylinder length="0.30" radius="0.298"/>
      </geometry>
      <!-- <geometry> <mesh filename="$(find j8_xacro_model)/meshes/${name}.STL"/>
        </geometry>-->
      <material name="">
        <color rgba="0.792156862745098 0.819607843137255 0.933333333333333 1"/>
      </material>
    </visual>
    <collision>
      <origin rpy="1.5707963267948966 0 0" xyz="0 0 0"/>
      <geometry>
        <cylinder length="0.30" radius="0.298"/>
      </geometry>
      <!-- <geometry>
          <mesh filename="$(find j8_xacro_model)/meshes/${name}.STL"/>
        </geometry>-->
    </collision>
  </link>
  <gazebo reference="Wheel_1">
    <visual>
      <material>
        <ambient>0.0 0.0 0.0 1.0</ambient>
        <diffuse>0.0 0.0 0.0 1.0</diffuse>
        <specular>0.0 0.0 0.0 1.0</specular>
        <emissive>0 0 0 0</emissive>
      </material>
    </visual>
    <preserveFixedJoint>true</preserveFixedJoint>
    <!-- Also preserve joint if has a fixed joint -->
  </gazebo>
  <gazebo reference="Wheel_1">
    <kp>100000000000000.0</kp>
    <kd>0.8</kd>
    <mu>0.25</mu>
    <mu2>0.25</mu2>
    <fdir1> 1 0 0</fdir1>
  </gazebo>
  <joint name="Suspension_1_Wheel_1_joint" type="continuous">
    <origin rpy="0 0 0" xyz="0.0 -0.18 0.0"/>
    <parent link="Suspension_1"/>
    <child link="Wheel_1"/>
    <axis xyz="0 1 0"/>
  </joint>
  <gazebo reference="Suspension_1_Wheel_1_joint">

    </gazebo>
  <!-- Suspension Link -->
  <link name="Suspension_2">
    <inertial>
      <origin rpy="0 0 0" xyz="4.4409E-16 -0.005 2.2204E-16"/>
      <mass value="10.0"/>
      <inertia ixx="5.0" ixy="8.0515E-20" ixz="0" iyy="5.0" iyz="1.9328E-19" izz="5.0"/>
    </inertial>
    <visual>
      <origin rpy="0 0 0" xyz="0 0 0"/>
      <geometry>
        <mesh filename="package://my_robot_description/meshes/Suspension_2.STL"/>
      </geometry>
      <material name="">
        <color rgba="0.79216 0.81961 0.93333 1"/>
      </material>
    </visual>
    <collision>
      <origin rpy="0 0 0" xyz="0 0 0"/>
      <geometry>
        <mesh filename="package://my_robot_description/meshes/Suspension_2.STL"/>
      </geometry>
    </collision>
  </link>
  <!-- Prismatic Joint (Base Link to Suspension) -->
  <joint name="base_Suspension_2_joint" type="prismatic">
    <origin rpy=" 0 0 0 " xyz="-0.36934 -0.45 -0.225"/>
    <parent link="base_link"/>
    <child link="Suspension_2"/>
    <axis xyz="0 0 1"/>
    <limit effort="1000000000000.0" lower="-10.0" upper="10.0" velocity="0.0"/>
    <dynamics damping="100.0" friction="1000000000000.0"/>
  </joint>
  <gazebo reference="base_Suspension_2_joint">
    <implicitSpringDamper>true</implicitSpringDamper>
    <springStiffness>500000000000000</springStiffness>
    <springReference>0.0</springReference>
  </gazebo>
  <link name="Wheel_2">
    <!-- Inertial, visual, and collision properties -->
    <inertial>
      <origin rpy="0 0 0" xyz="0 0.17637 0"/>
      <mass value="5.205463824313"/>
      <inertia ixx="3.66317923670982" ixy="0" ixz="0" iyy="3.66317923670982" iyz="0" izz="5.43484629444829"/>
    </inertial>
    <visual>
      <origin rpy="1.5707963267948966 0 0" xyz="0 0 0"/>
      <geometry>
        <cylinder length="0.30" radius="0.298"/>
      </geometry>
      <!-- <geometry> <mesh filename="$(find j8_xacro_model)/meshes/${name}.STL"/>
        </geometry>-->
      <material name="">
        <color rgba="0.792156862745098 0.819607843137255 0.933333333333333 1"/>
      </material>
    </visual>
    <collision>
      <origin rpy="1.5707963267948966 0 0" xyz="0 0 0"/>
      <geometry>
        <cylinder length="0.30" radius="0.298"/>
      </geometry>
      <!-- <geometry>
          <mesh filename="$(find j8_xacro_model)/meshes/${name}.STL"/>
        </geometry>-->
    </collision>
  </link>
  <gazebo reference="Wheel_2">
    <visual>
      <material>
        <ambient>0.0 0.0 0.0 1.0</ambient>
        <diffuse>0.0 0.0 0.0 1.0</diffuse>
        <specular>0.0 0.0 0.0 1.0</specular>
        <emissive>0 0 0 0</emissive>
      </material>
    </visual>
    <preserveFixedJoint>true</preserveFixedJoint>
    <!-- Also preserve joint if has a fixed joint -->
  </gazebo>
  <gazebo reference="Wheel_2">
    <kp>100000000000000.0</kp>
    <kd>0.8</kd>
    <mu>0.25</mu>
    <mu2>0.25</mu2>
    <fdir1> 1 0 0</fdir1>
  </gazebo>
  <joint name="Suspension_2_Wheel_2_joint" type="continuous">
    <origin rpy="0 0 0" xyz="0.0 -0.18 0.0"/>
    <parent link="Suspension_2"/>
    <child link="Wheel_2"/>
    <axis xyz="0 1 0"/>
  </joint>
  <gazebo reference="Suspension_2_Wheel_2_joint">

    </gazebo>
  <!-- Suspension Link -->
  <link name="Suspension_3">
    <inertial>
      <origin rpy="0 0 0" xyz="4.4409E-16 -0.005 2.2204E-16"/>
      <mass value="10.0"/>
      <inertia ixx="5.0" ixy="8.0515E-20" ixz="0" iyy="5.0" iyz="1.9328E-19" izz="5.0"/>
    </inertial>
    <visual>
      <origin rpy="0 0 0" xyz="0 0 0"/>
      <geometry>
        <mesh filename="package://my_robot_description/meshes/Suspension_3.STL"/>
      </geometry>
      <material name="">
        <color rgba="0.79216 0.81961 0.93333 1"/>
      </material>
    </visual>
    <collision>
      <origin rpy="0 0 0" xyz="0 0 0"/>
      <geometry>
        <mesh filename="package://my_robot_description/meshes/Suspension_3.STL"/>
      </geometry>
    </collision>
  </link>
  <!-- Prismatic Joint (Base Link to Suspension) -->
  <joint name="base_Suspension_3_joint" type="prismatic">
    <origin rpy=" 0 0 0 " xyz="0.32066 -0.45 -0.225"/>
    <parent link="base_link"/>
    <child link="Suspension_3"/>
    <axis xyz="0 0 1"/>
    <limit effort="1000000000000.0" lower="-10.0" upper="10.0" velocity="0.0"/>
    <dynamics damping="100.0" friction="1000000000000.0"/>
  </joint>
  <gazebo reference="base_Suspension_3_joint">
    <implicitSpringDamper>true</implicitSpringDamper>
    <springStiffness>500000000000000</springStiffness>
    <springReference>0.0</springReference>
  </gazebo>
  <link name="Wheel_3">
    <!-- Inertial, visual, and collision properties -->
    <inertial>
      <origin rpy="0 0 0" xyz="0 0.17637 0"/>
      <mass value="5.205463824313"/>
      <inertia ixx="3.66317923670982" ixy="0" ixz="0" iyy="3.66317923670982" iyz="0" izz="5.43484629444829"/>
    </inertial>
    <visual>
      <origin rpy="1.5707963267948966 0 0" xyz="0 0 0"/>
      <geometry>
        <cylinder length="0.30" radius="0.298"/>
      </geometry>
      <!-- <geometry> <mesh filename="$(find j8_xacro_model)/meshes/${name}.STL"/>
        </geometry>-->
      <material name="">
        <color rgba="0.792156862745098 0.819607843137255 0.933333333333333 1"/>
      </material>
    </visual>
    <collision>
      <origin rpy="1.5707963267948966 0 0" xyz="0 0 0"/>
      <geometry>
        <cylinder length="0.30" radius="0.298"/>
      </geometry>
      <!-- <geometry>
          <mesh filename="$(find j8_xacro_model)/meshes/${name}.STL"/>
        </geometry>-->
    </collision>
  </link>
  <gazebo reference="Wheel_3">
    <visual>
      <material>
        <ambient>0.0 0.0 0.0 1.0</ambient>
        <diffuse>0.0 0.0 0.0 1.0</diffuse>
        <specular>0.0 0.0 0.0 1.0</specular>
        <emissive>0 0 0 0</emissive>
      </material>
    </visual>
    <preserveFixedJoint>true</preserveFixedJoint>
    <!-- Also preserve joint if has a fixed joint -->
  </gazebo>
  <gazebo reference="Wheel_3">
    <kp>100000000000000.0</kp>
    <kd>0.8</kd>
    <mu>0.25</mu>
    <mu2>0.25</mu2>
    <fdir1> 1 0 0</fdir1>
  </gazebo>
  <joint name="Suspension_3_Wheel_3_joint" type="continuous">
    <origin rpy="0 0 0" xyz="0.0 -0.18 0.0"/>
    <parent link="Suspension_3"/>
    <child link="Wheel_3"/>
    <axis xyz="0 1 0"/>
  </joint>
  <gazebo reference="Suspension_3_Wheel_3_joint">

    </gazebo>
  <!-- Suspension Link -->
  <link name="Suspension_4">
    <inertial>
      <origin rpy="0 0 0" xyz="4.4409E-16 -0.005 2.2204E-16"/>
      <mass value="10.0"/>
      <inertia ixx="5.0" ixy="8.0515E-20" ixz="0" iyy="5.0" iyz="1.9328E-19" izz="5.0"/>
    </inertial>
    <visual>
      <origin rpy="0 0 0" xyz="0 0 0"/>
      <geometry>
        <mesh filename="package://my_robot_description/meshes/Suspension_4.STL"/>
      </geometry>
      <material name="">
        <color rgba="0.79216 0.81961 0.93333 1"/>
      </material>
    </visual>
    <collision>
      <origin rpy="0 0 0" xyz="0 0 0"/>
      <geometry>
        <mesh filename="package://my_robot_description/meshes/Suspension_4.STL"/>
      </geometry>
    </collision>
  </link>
  <!-- Prismatic Joint (Base Link to Suspension) -->
  <joint name="base_Suspension_4_joint" type="prismatic">
    <origin rpy=" 0 0 0 " xyz="1.0107 -0.45 -0.225"/>
    <parent link="base_link"/>
    <child link="Suspension_4"/>
    <axis xyz="0 0 1"/>
    <limit effort="1000000000000.0" lower="-10.0" upper="10.0" velocity="0.0"/>
    <dynamics damping="100.0" friction="1000000000000.0"/>
  </joint>
  <gazebo reference="base_Suspension_4_joint">
    <implicitSpringDamper>true</implicitSpringDamper>
    <springStiffness>500000000000000</springStiffness>
    <springReference>0.0</springReference>
  </gazebo>
  <link name="Wheel_4">
    <!-- Inertial, visual, and collision properties -->
    <inertial>
      <origin rpy="0 0 0" xyz="0 0.17637 0"/>
      <mass value="5.205463824313"/>
      <inertia ixx="3.66317923670982" ixy="0" ixz="0" iyy="3.66317923670982" iyz="0" izz="5.43484629444829"/>
    </inertial>
    <visual>
      <origin rpy="1.5707963267948966 0 0" xyz="0 0 0"/>
      <geometry>
        <cylinder length="0.30" radius="0.298"/>
      </geometry>
      <!-- <geometry> <mesh filename="$(find j8_xacro_model)/meshes/${name}.STL"/>
        </geometry>-->
      <material name="">
        <color rgba="0.792156862745098 0.819607843137255 0.933333333333333 1"/>
      </material>
    </visual>
    <collision>
      <origin rpy="1.5707963267948966 0 0" xyz="0 0 0"/>
      <geometry>
        <cylinder length="0.30" radius="0.298"/>
      </geometry>
      <!-- <geometry>
          <mesh filename="$(find j8_xacro_model)/meshes/${name}.STL"/>
        </geometry>-->
    </collision>
  </link>
  <gazebo reference="Wheel_4">
    <visual>
      <material>
        <ambient>0.0 0.0 0.0 1.0</ambient>
        <diffuse>0.0 0.0 0.0 1.0</diffuse>
        <specular>0.0 0.0 0.0 1.0</specular>
        <emissive>0 0 0 0</emissive>
      </material>
    </visual>
    <preserveFixedJoint>true</preserveFixedJoint>
    <!-- Also preserve joint if has a fixed joint -->
  </gazebo>
  <gazebo reference="Wheel_4">
    <kp>100000000000000.0</kp>
    <kd>0.8</kd>
    <mu>0.25</mu>
    <mu2>0.25</mu2>
    <fdir1> 1 0 0</fdir1>
  </gazebo>
  <joint name="Suspension_4_Wheel_4_joint" type="continuous">
    <origin rpy="0 0 0" xyz="0.0 -0.18 0.0"/>
    <parent link="Suspension_4"/>
    <child link="Wheel_4"/>
    <axis xyz="0 1 0"/>
  </joint>
  <gazebo reference="Suspension_4_Wheel_4_joint">

    </gazebo>
  <!-- Suspension Link -->
  <link name="Suspension_5">
    <inertial>
      <origin rpy="0 0 0" xyz="4.4409E-16 -0.005 2.2204E-16"/>
      <mass value="10.0"/>
      <inertia ixx="5.0" ixy="8.0515E-20" ixz="0" iyy="5.0" iyz="1.9328E-19" izz="5.0"/>
    </inertial>
    <visual>
      <origin rpy="0 0 0" xyz="0 0 0"/>
      <geometry>
        <mesh filename="package://my_robot_description/meshes/Suspension_5.STL"/>
      </geometry>
      <material name="">
        <color rgba="0.79216 0.81961 0.93333 1"/>
      </material>
    </visual>
    <collision>
      <origin rpy="0 0 0" xyz="0 0 0"/>
      <geometry>
        <mesh filename="package://my_robot_description/meshes/Suspension_5.STL"/>
      </geometry>
    </collision>
  </link>
  <!-- Prismatic Joint (Base Link to Suspension) -->
  <joint name="base_Suspension_5_joint" type="prismatic">
    <origin rpy=" 0 0 0 " xyz="-1.0593 0.45 -0.225"/>
    <parent link="base_link"/>
    <child link="Suspension_5"/>
    <axis xyz="0 0 1"/>
    <limit effort="1000000000000.0" lower="-10.0" upper="10.0" velocity="0.0"/>
    <dynamics damping="100.0" friction="1000000000000.0"/>
  </joint>
  <gazebo reference="base_Suspension_5_joint">
    <implicitSpringDamper>true</implicitSpringDamper>
    <springStiffness>500000000000000</springStiffness>
    <springReference>0.0</springReference>
  </gazebo>
  <link name="Wheel_5">
    <!-- Inertial, visual, and collision properties -->
    <inertial>
      <origin rpy="0 0 0" xyz="0 0.17637 0"/>
      <mass value="5.205463824313"/>
      <inertia ixx="3.66317923670982" ixy="0" ixz="0" iyy="3.66317923670982" iyz="0" izz="5.43484629444829"/>
    </inertial>
    <visual>
      <origin rpy="1.5707963267948966 0 0" xyz="0 0 0"/>
      <geometry>
        <cylinder length="0.30" radius="0.298"/>
      </geometry>
      <!-- <geometry> <mesh filename="$(find j8_xacro_model)/meshes/${name}.STL"/>
        </geometry>-->
      <material name="">
        <color rgba="0.792156862745098 0.819607843137255 0.933333333333333 1"/>
      </material>
    </visual>
    <collision>
      <origin rpy="1.5707963267948966 0 0" xyz="0 0 0"/>
      <geometry>
        <cylinder length="0.30" radius="0.298"/>
      </geometry>
      <!-- <geometry>
          <mesh filename="$(find j8_xacro_model)/meshes/${name}.STL"/>
        </geometry>-->
    </collision>
  </link>
  <gazebo reference="Wheel_5">
    <visual>
      <material>
        <ambient>0.0 0.0 0.0 1.0</ambient>
        <diffuse>0.0 0.0 0.0 1.0</diffuse>
        <specular>0.0 0.0 0.0 1.0</specular>
        <emissive>0 0 0 0</emissive>
      </material>
    </visual>
    <preserveFixedJoint>true</preserveFixedJoint>
    <!-- Also preserve joint if has a fixed joint -->
  </gazebo>
  <gazebo reference="Wheel_5">
    <kp>100000000000000.0</kp>
    <kd>0.8</kd>
    <mu>0.25</mu>
    <mu2>0.25</mu2>
    <fdir1> 1 0 0</fdir1>
  </gazebo>
  <joint name="Suspension_5_Wheel_5_joint" type="continuous">
    <origin rpy="0 0 0" xyz="0.0 0.18 0.0"/>
    <parent link="Suspension_5"/>
    <child link="Wheel_5"/>
    <axis xyz="0 1 0"/>
  </joint>
  <gazebo reference="Suspension_5_Wheel_5_joint">

    </gazebo>
  <!-- Suspension Link -->
  <link name="Suspension_6">
    <inertial>
      <origin rpy="0 0 0" xyz="4.4409E-16 -0.005 2.2204E-16"/>
      <mass value="10.0"/>
      <inertia ixx="5.0" ixy="8.0515E-20" ixz="0" iyy="5.0" iyz="1.9328E-19" izz="5.0"/>
    </inertial>
    <visual>
      <origin rpy="0 0 0" xyz="0 0 0"/>
      <geometry>
        <mesh filename="package://my_robot_description/meshes/Suspension_6.STL"/>
      </geometry>
      <material name="">
        <color rgba="0.79216 0.81961 0.93333 1"/>
      </material>
    </visual>
    <collision>
      <origin rpy="0 0 0" xyz="0 0 0"/>
      <geometry>
        <mesh filename="package://my_robot_description/meshes/Suspension_6.STL"/>
      </geometry>
    </collision>
  </link>
  <!-- Prismatic Joint (Base Link to Suspension) -->
  <joint name="base_Suspension_6_joint" type="prismatic">
    <origin rpy=" 0 0 0 " xyz="-0.36934 0.45 -0.225"/>
    <parent link="base_link"/>
    <child link="Suspension_6"/>
    <axis xyz="0 0 1"/>
    <limit effort="1000000000000.0" lower="-10.0" upper="10.0" velocity="0.0"/>
    <dynamics damping="100.0" friction="1000000000000.0"/>
  </joint>
  <gazebo reference="base_Suspension_6_joint">
    <implicitSpringDamper>true</implicitSpringDamper>
    <springStiffness>500000000000000</springStiffness>
    <springReference>0.0</springReference>
  </gazebo>
  <link name="Wheel_6">
    <!-- Inertial, visual, and collision properties -->
    <inertial>
      <origin rpy="0 0 0" xyz="0 0.17637 0"/>
      <mass value="5.205463824313"/>
      <inertia ixx="3.66317923670982" ixy="0" ixz="0" iyy="3.66317923670982" iyz="0" izz="5.43484629444829"/>
    </inertial>
    <visual>
      <origin rpy="1.5707963267948966 0 0" xyz="0 0 0"/>
      <geometry>
        <cylinder length="0.30" radius="0.298"/>
      </geometry>
      <!-- <geometry> <mesh filename="$(find j8_xacro_model)/meshes/${name}.STL"/>
        </geometry>-->
      <material name="">
        <color rgba="0.792156862745098 0.819607843137255 0.933333333333333 1"/>
      </material>
    </visual>
    <collision>
      <origin rpy="1.5707963267948966 0 0" xyz="0 0 0"/>
      <geometry>
        <cylinder length="0.30" radius="0.298"/>
      </geometry>
      <!-- <geometry>
          <mesh filename="$(find j8_xacro_model)/meshes/${name}.STL"/>
        </geometry>-->
    </collision>
  </link>
  <gazebo reference="Wheel_6">
    <visual>
      <material>
        <ambient>0.0 0.0 0.0 1.0</ambient>
        <diffuse>0.0 0.0 0.0 1.0</diffuse>
        <specular>0.0 0.0 0.0 1.0</specular>
        <emissive>0 0 0 0</emissive>
      </material>
    </visual>
    <preserveFixedJoint>true</preserveFixedJoint>
    <!-- Also preserve joint if has a fixed joint -->
  </gazebo>
  <gazebo reference="Wheel_6">
    <kp>100000000000000.0</kp>
    <kd>0.8</kd>
    <mu>0.25</mu>
    <mu2>0.25</mu2>
    <fdir1> 1 0 0</fdir1>
  </gazebo>
  <joint name="Suspension_6_Wheel_6_joint" type="continuous">
    <origin rpy="0 0 0" xyz="0.0 0.18 0.0"/>
    <parent link="Suspension_6"/>
    <child link="Wheel_6"/>
    <axis xyz="0 1 0"/>
  </joint>
  <gazebo reference="Suspension_6_Wheel_6_joint">

    </gazebo>
  <!-- Suspension Link -->
  <link name="Suspension_7">
    <inertial>
      <origin rpy="0 0 0" xyz="4.4409E-16 -0.005 2.2204E-16"/>
      <mass value="10.0"/>
      <inertia ixx="5.0" ixy="8.0515E-20" ixz="0" iyy="5.0" iyz="1.9328E-19" izz="5.0"/>
    </inertial>
    <visual>
      <origin rpy="0 0 0" xyz="0 0 0"/>
      <geometry>
        <mesh filename="package://my_robot_description/meshes/Suspension_7.STL"/>
      </geometry>
      <material name="">
        <color rgba="0.79216 0.81961 0.93333 1"/>
      </material>
    </visual>
    <collision>
      <origin rpy="0 0 0" xyz="0 0 0"/>
      <geometry>
        <mesh filename="package://my_robot_description/meshes/Suspension_7.STL"/>
      </geometry>
    </collision>
  </link>
  <!-- Prismatic Joint (Base Link to Suspension) -->
  <joint name="base_Suspension_7_joint" type="prismatic">
    <origin rpy=" 0 0 0 " xyz="0.32066 0.45 -0.225"/>
    <parent link="base_link"/>
    <child link="Suspension_7"/>
    <axis xyz="0 0 1"/>
    <limit effort="1000000000000.0" lower="-10.0" upper="10.0" velocity="0.0"/>
    <dynamics damping="100.0" friction="1000000000000.0"/>
  </joint>
  <gazebo reference="base_Suspension_7_joint">
    <implicitSpringDamper>true</implicitSpringDamper>
    <springStiffness>500000000000000</springStiffness>
    <springReference>0.0</springReference>
  </gazebo>
  <link name="Wheel_7">
    <!-- Inertial, visual, and collision properties -->
    <inertial>
      <origin rpy="0 0 0" xyz="0 0.17637 0"/>
      <mass value="5.205463824313"/>
      <inertia ixx="3.66317923670982" ixy="0" ixz="0" iyy="3.66317923670982" iyz="0" izz="5.43484629444829"/>
    </inertial>
    <visual>
      <origin rpy="1.5707963267948966 0 0" xyz="0 0 0"/>
      <geometry>
        <cylinder length="0.30" radius="0.298"/>
      </geometry>
      <!-- <geometry> <mesh filename="$(find j8_xacro_model)/meshes/${name}.STL"/>
        </geometry>-->
      <material name="">
        <color rgba="0.792156862745098 0.819607843137255 0.933333333333333 1"/>
      </material>
    </visual>
    <collision>
      <origin rpy="1.5707963267948966 0 0" xyz="0 0 0"/>
      <geometry>
        <cylinder length="0.30" radius="0.298"/>
      </geometry>
      <!-- <geometry>
          <mesh filename="$(find j8_xacro_model)/meshes/${name}.STL"/>
        </geometry>-->
    </collision>
  </link>
  <gazebo reference="Wheel_7">
    <visual>
      <material>
        <ambient>0.0 0.0 0.0 1.0</ambient>
        <diffuse>0.0 0.0 0.0 1.0</diffuse>
        <specular>0.0 0.0 0.0 1.0</specular>
        <emissive>0 0 0 0</emissive>
      </material>
    </visual>
    <preserveFixedJoint>true</preserveFixedJoint>
    <!-- Also preserve joint if has a fixed joint -->
  </gazebo>
  <gazebo reference="Wheel_7">
    <kp>100000000000000.0</kp>
    <kd>0.8</kd>
    <mu>0.25</mu>
    <mu2>0.25</mu2>
    <fdir1> 1 0 0</fdir1>
  </gazebo>
  <joint name="Suspension_7_Wheel_7_joint" type="continuous">
    <origin rpy="0 0 0" xyz="0.0 0.18 0.0"/>
    <parent link="Suspension_7"/>
    <child link="Wheel_7"/>
    <axis xyz="0 1 0"/>
  </joint>
  <gazebo reference="Suspension_7_Wheel_7_joint">

    </gazebo>
  <!-- Suspension Link -->
  <link name="Suspension_8">
    <inertial>
      <origin rpy="0 0 0" xyz="4.4409E-16 -0.005 2.2204E-16"/>
      <mass value="10.0"/>
      <inertia ixx="5.0" ixy="8.0515E-20" ixz="0" iyy="5.0" iyz="1.9328E-19" izz="5.0"/>
    </inertial>
    <visual>
      <origin rpy="0 0 0" xyz="0 0 0"/>
      <geometry>
        <mesh filename="package://my_robot_description/meshes/Suspension_8.STL"/>
      </geometry>
      <material name="">
        <color rgba="0.79216 0.81961 0.93333 1"/>
      </material>
    </visual>
    <collision>
      <origin rpy="0 0 0" xyz="0 0 0"/>
      <geometry>
        <mesh filename="package://my_robot_description/meshes/Suspension_8.STL"/>
      </geometry>
    </collision>
  </link>
  <!-- Prismatic Joint (Base Link to Suspension) -->
  <joint name="base_Suspension_8_joint" type="prismatic">
    <origin rpy=" 0 0 0 " xyz="1.0107 0.45 -0.225"/>
    <parent link="base_link"/>
    <child link="Suspension_8"/>
    <axis xyz="0 0 1"/>
    <limit effort="1000000000000.0" lower="-10.0" upper="10.0" velocity="0.0"/>
    <dynamics damping="100.0" friction="1000000000000.0"/>
  </joint>
  <gazebo reference="base_Suspension_8_joint">
    <implicitSpringDamper>true</implicitSpringDamper>
    <springStiffness>500000000000000</springStiffness>
    <springReference>0.0</springReference>
  </gazebo>
  <link name="Wheel_8">
    <!-- Inertial, visual, and collision properties -->
    <inertial>
      <origin rpy="0 0 0" xyz="0 0.17637 0"/>
      <mass value="5.205463824313"/>
      <inertia ixx="3.66317923670982" ixy="0" ixz="0" iyy="3.66317923670982" iyz="0" izz="5.43484629444829"/>
    </inertial>
    <visual>
      <origin rpy="1.5707963267948966 0 0" xyz="0 0 0"/>
      <geometry>
        <cylinder length="0.30" radius="0.298"/>
      </geometry>
      <!-- <geometry> <mesh filename="$(find j8_xacro_model)/meshes/${name}.STL"/>
        </geometry>-->
      <material name="">
        <color rgba="0.792156862745098 0.819607843137255 0.933333333333333 1"/>
      </material>
    </visual>
    <collision>
      <origin rpy="1.5707963267948966 0 0" xyz="0 0 0"/>
      <geometry>
        <cylinder length="0.30" radius="0.298"/>
      </geometry>
      <!-- <geometry>
          <mesh filename="$(find j8_xacro_model)/meshes/${name}.STL"/>
        </geometry>-->
    </collision>
  </link>
  <gazebo reference="Wheel_8">
    <visual>
      <material>
        <ambient>0.0 0.0 0.0 1.0</ambient>
        <diffuse>0.0 0.0 0.0 1.0</diffuse>
        <specular>0.0 0.0 0.0 1.0</specular>
        <emissive>0 0 0 0</emissive>
      </material>
    </visual>
    <preserveFixedJoint>true</preserveFixedJoint>
    <!-- Also preserve joint if has a fixed joint -->
  </gazebo>
  <gazebo reference="Wheel_8">
    <kp>100000000000000.0</kp>
    <kd>0.8</kd>
    <mu>0.25</mu>
    <mu2>0.25</mu2>
    <fdir1> 1 0 0</fdir1>
  </gazebo>
  <joint name="Suspension_8_Wheel_8_joint" type="continuous">
    <origin rpy="0 0 0" xyz="0.0 0.18 0.0"/>
    <parent link="Suspension_8"/>
    <child link="Wheel_8"/>
    <axis xyz="0 1 0"/>
  </joint>
  <gazebo reference="Suspension_8_Wheel_8_joint">

    </gazebo>
  <link name="Fixposion_base">
    <inertial>
      <origin rpy="0 0 0" xyz="-0.20204 0.0024993 0.014284"/>
      <mass value="0.33336"/>
      <inertia ixx="0.00093999" ixy="-5.8116E-11" ixz="1.8511E-08" iyy="0.0045678" iyz="-1.727E-08" izz="0.0036292"/>
    </inertial>
    <visual>
      <origin rpy="0 0 0" xyz="0 0 0"/>
      <geometry>
        <mesh filename="package://my_robot_description/meshes/Fixposion_base.STL"/>
      </geometry>
      <material name="">
        <color rgba="0.25098 0.25098 0.25098 0.2"/>
      </material>
    </visual>
    <collision>
      <origin rpy="0 0 0" xyz="0 0 0"/>
      <geometry>
        <mesh filename="package://my_robot_description/meshes/Fixposion_base.STL"/>
      </geometry>
    </collision>
  </link>
  <gazebo reference="Fixposion_base">
    <visual>
      <material>
        <ambient>0.0 0.0 0.0 1.0</ambient>
        <diffuse>0.0 0.0 0.0 1.0</diffuse>
        <specular>0.0 0.0 0.0 1.0</specular>
        <emissive>0 0 0 0</emissive>
      </material>
    </visual>
    <preserveFixedJoint>true</preserveFixedJoint>
    <!-- Also preserve joint if has a fixed joint -->
  </gazebo>
  <!-- Black-->
  <joint name="Bridge_fixposion_base_joint" type="fixed">
    <origin rpy="1.5708 0 1.5708" xyz="-0.0028148 -0.11697 0.21171"/>
    <parent link="Bridge"/>
    <child link="Fixposion_base"/>
    <axis xyz="0 0 0"/>
  </joint>
  <link name="Left_fixposition_feet">
    <inertial>
      <origin rpy="0 0 0" xyz="0.034556 0.032987 2.2204E-16"/>
      <mass value="0.079938"/>
      <inertia ixx="6.1363E-05" ixy="-7.2002E-06" ixz="6.4262E-21" iyy="2.1739E-05" iyz="-2.7645E-20" izz="5.4705E-05"/>
    </inertial>
    <visual>
      <origin rpy="0 0 0" xyz="0 0 0"/>
      <geometry>
        <mesh filename="package://my_robot_description/meshes/Left_fixposition_feet.STL"/>
      </geometry>
      <material name="">
        <color rgba="0.64706 0.92549 0.90196 1"/>
      </material>
    </visual>
    <collision>
      <origin rpy="0 0 0" xyz="0 0 0"/>
      <geometry>
        <mesh filename="package://my_robot_description/meshes/Left_fixposition_feet.STL"/>
      </geometry>
    </collision>
  </link>
  <gazebo reference="Left_fixposition_feet">
    <visual>
      <material>
        <ambient>0.2941 0.3255 0.1255 1.0</ambient>
        <diffuse>0.2941 0.3255 0.1255 1.0</diffuse>
        <specular>0.2941 0.3255 0.1255 1.0</specular>
        <emissive>0 0 0 0</emissive>
      </material>
    </visual>
    <preserveFixedJoint>true</preserveFixedJoint>
    <!-- Also preserve joint if has a fixed joint -->
  </gazebo>
  <!-- Military Green -->
  <joint name="Left_fixposition_feet_joint" type="fixed">
    <origin rpy="3.1416 0 3.1416" xyz="-0.060832 0.005 0.052821"/>
    <parent link="Fixposion_base"/>
    <child link="Left_fixposition_feet"/>
    <axis xyz="0 0 0"/>
  </joint>
  <link name="Left_fixposition_holder">
    <inertial>
      <origin rpy="0 0 0" xyz="9.6982E-09 0.016739 0.01561"/>
      <mass value="0.010272"/>
      <inertia ixx="9.9327E-07" ixy="2.2546E-12" ixz="-6.9048E-13" iyy="1.0096E-06" iyz="-6.4195E-12" izz="1.5191E-06"/>
    </inertial>
    <visual>
      <origin rpy="0 0 0" xyz="0 0 0"/>
      <geometry>
        <mesh filename="package://my_robot_description/meshes/Left_fixposition_holder.STL"/>
      </geometry>
      <material name="">
        <color rgba="0.79216 0.81961 0.93333 1"/>
      </material>
    </visual>
    <collision>
      <origin rpy="0 0 0" xyz="0 0 0"/>
      <geometry>
        <mesh filename="package://my_robot_description/meshes/Left_fixposition_holder.STL"/>
      </geometry>
    </collision>
  </link>
  <gazebo reference="Left_fixposition_holder">
    <visual>
      <material>
        <ambient>0.0 0.0 0.0 1.0</ambient>
        <diffuse>0.0 0.0 0.0 1.0</diffuse>
        <specular>0.0 0.0 0.0 1.0</specular>
        <emissive>0 0 0 0</emissive>
      </material>
    </visual>
    <preserveFixedJoint>true</preserveFixedJoint>
    <!-- Also preserve joint if has a fixed joint -->
  </gazebo>
  <!-- Black -->
  <joint name="Left_fixposition_holder_joint" type="fixed">
    <origin rpy="0 1.5708 0" xyz="0.022601 0.078 0.00025"/>
    <parent link="Left_fixposition_feet"/>
    <child link="Left_fixposition_holder"/>
    <axis xyz="0 0 0"/>
  </joint>
  <link name="Central_fixposition_feet">
    <inertial>
      <origin rpy="0 0 0" xyz="-0.0036553 0.032987 0.02961"/>
      <mass value="0.079938"/>
      <inertia ixx="6.1363E-05" ixy="-7.2002E-06" ixz="-2.22E-19" iyy="2.1739E-05" iyz="2.8819E-19" izz="5.4705E-05"/>
    </inertial>
    <visual>
      <origin rpy="0 0 0" xyz="0 0 0"/>
      <geometry>
        <mesh filename="package://my_robot_description/meshes/Central_fixposition_feet.STL"/>
      </geometry>
      <material name="">
        <color rgba="0.64706 0.92549 0.90196 1"/>
      </material>
    </visual>
    <collision>
      <origin rpy="0 0 0" xyz="0 0 0"/>
      <geometry>
        <mesh filename="package://my_robot_description/meshes/Central_fixposition_feet.STL"/>
      </geometry>
    </collision>
  </link>
  <gazebo reference="Central_fixposition_feet">
    <visual>
      <material>
        <ambient>0.2941 0.3255 0.1255 1.0</ambient>
        <diffuse>0.2941 0.3255 0.1255 1.0</diffuse>
        <specular>0.2941 0.3255 0.1255 1.0</specular>
        <emissive>0 0 0 0</emissive>
      </material>
    </visual>
    <preserveFixedJoint>true</preserveFixedJoint>
    <!-- Also preserve joint if has a fixed joint -->
  </gazebo>
  <!-- Military Green -->
  <joint name="Central_fixposition_feet_joint" type="fixed">
    <origin rpy="0.0 -1.5708 0" xyz="-0.17218 0.005 -0.013029"/>
    <parent link="Fixposion_base"/>
    <child link="Central_fixposition_feet"/>
    <axis xyz="0 0 0"/>
  </joint>
  <link name="Central_fixposition_holder">
    <inertial>
      <origin rpy="0 0 0" xyz="-0.02161 0.016739 -3.809E-08"/>
      <mass value="0.010272"/>
      <inertia ixx="9.9327E-07" ixy="2.2546E-12" ixz="-6.9048E-13" iyy="1.0096E-06" iyz="-6.4195E-12" izz="1.5191E-06"/>
    </inertial>
    <visual>
      <origin rpy="0 0 0" xyz="0 0 0"/>
      <geometry>
        <mesh filename="package://my_robot_description/meshes/Central_fixposition_holder.STL"/>
      </geometry>
      <material name="">
        <color rgba="0.79216 0.81961 0.93333 1"/>
      </material>
    </visual>
    <collision>
      <origin rpy="0 0 0" xyz="0 0 0"/>
      <geometry>
        <mesh filename="package://my_robot_description/meshes/Central_fixposition_holder.STL"/>
      </geometry>
    </collision>
  </link>
  <gazebo reference="Central_fixposition_holder">
    <visual>
      <material>
        <ambient>0.2941 0.3255 0.1255 1.0</ambient>
        <diffuse>0.2941 0.3255 0.1255 1.0</diffuse>
        <specular>0.2941 0.3255 0.1255 1.0</specular>
        <emissive>0 0 0 0</emissive>
      </material>
    </visual>
    <preserveFixedJoint>true</preserveFixedJoint>
    <!-- Also preserve joint if has a fixed joint -->
  </gazebo>
  <!-- Black -->
  <joint name="Central_fixposition_holder_joint" type="fixed">
    <origin rpy="0 1.5708 0" xyz="0 0.078 0.00825"/>
    <parent link="Central_fixposition_feet"/>
    <child link="Central_fixposition_holder"/>
    <axis xyz="0 0 0"/>
  </joint>
  <link name="Right_fixposition_feet">
    <inertial>
      <origin rpy="0 0 0" xyz="-0.021265 0.032987 -3.3307E-16"/>
      <mass value="0.079938"/>
      <inertia ixx="6.1363E-05" ixy="-7.2002E-06" ixz="3.2408E-21" iyy="2.1739E-05" iyz="-1.2404E-20" izz="5.4705E-05"/>
    </inertial>
    <visual>
      <origin rpy="0 0 0" xyz="0 0 0"/>
      <geometry>
        <mesh filename="package://my_robot_description/meshes/Right_fixposition_feet.STL"/>
      </geometry>
      <material name="">
        <color rgba="0.64706 0.92549 0.90196 1"/>
      </material>
    </visual>
    <collision>
      <origin rpy="0 0 0" xyz="0 0 0"/>
      <geometry>
        <mesh filename="package://my_robot_description/meshes/Right_fixposition_feet.STL"/>
      </geometry>
    </collision>
  </link>
  <gazebo reference="Right_fixposition_feet">
    <visual>
      <material>
        <ambient>0.2941 0.3255 0.1255 1.0</ambient>
        <diffuse>0.2941 0.3255 0.1255 1.0</diffuse>
        <specular>0.2941 0.3255 0.1255 1.0</specular>
        <emissive>0 0 0 0</emissive>
      </material>
    </visual>
    <preserveFixedJoint>true</preserveFixedJoint>
    <!-- Also preserve joint if has a fixed joint -->
  </gazebo>
  <!-- Black -->
  <joint name="Right_fixposition_feet_joint" type="fixed">
    <origin rpy="0 0 0" xyz="-0.28743 0.005 0.052321"/>
    <parent link="Fixposion_base"/>
    <child link="Right_fixposition_feet"/>
    <axis xyz="0 0 0"/>
  </joint>
  <link name="Right_fixposition_holder">
    <inertial>
      <origin rpy="0 0 0" xyz="9.6982E-09 0.016739 -0.01561"/>
      <mass value="0.010272"/>
      <inertia ixx="9.9327E-07" ixy="2.2546E-12" ixz="-6.9048E-13" iyy="1.0096E-06" iyz="-6.4195E-12" izz="1.5191E-06"/>
    </inertial>
    <visual>
      <origin rpy="0 0 0" xyz="0 0 0"/>
      <geometry>
        <mesh filename="package://my_robot_description/meshes/Right_fixposition_holder.STL"/>
      </geometry>
      <material name="">
        <color rgba="0.79216 0.81961 0.93333 1"/>
      </material>
    </visual>
    <collision>
      <origin rpy="0 0 0" xyz="0 0 0"/>
      <geometry>
        <mesh filename="package://my_robot_description/meshes/Right_fixposition_holder.STL"/>
      </geometry>
    </collision>
  </link>
  <gazebo reference="Right_fixposition_holder">
    <visual>
      <material>
        <ambient>0.0 0.0 0.0 1.0</ambient>
        <diffuse>0.0 0.0 0.0 1.0</diffuse>
        <specular>0.0 0.0 0.0 1.0</specular>
        <emissive>0 0 0 0</emissive>
      </material>
    </visual>
    <preserveFixedJoint>true</preserveFixedJoint>
    <!-- Also preserve joint if has a fixed joint -->
  </gazebo>
  <!-- Black -->
  <joint name="Right_fixposition_holder_holder" type="fixed">
    <origin rpy="0 1.5708 0" xyz="-0.002 0.078 0.00025"/>
    <parent link="Right_fixposition_feet"/>
    <child link="Right_fixposition_holder"/>
    <axis xyz="0 0 0"/>
  </joint>
  <!-- Fixposition sensor
  <xacro:fixposition_sensor parent="Bridge" xyz="-0.0028148 -0.11697 0.21171" rpy="1.5708 0 1.5708"/>-->
</robot>
